Workbook

Sheet مونتاژ ماشینی
A1: Date: | B1: 04/12/12 | C1: (APQP) رويه طرح ريزي پيشاپيش كيفيت محصول | F1: Product Name : | G1: PCBA_SMD(SBMi_P207_Soren_Arisun_B2 Sample)
A2: Version: | B2: V04 | F2: Technical No :
A3: Doc Code : | D3: BOM (Bill of Material) | F3: Customer: | J3: Arm Arm
A4: SCH Name : | B4: SBMi_F1K_B2.1 | F4: Provided by : | G4: P.Parsa
A5: Stock No : | B5: 1201653_F01 | F5: Checked by : | G5: H.Sargoli
A6: Page: | B6: 1 of 1 | F6: Approved by : | G6: A.Yeganeh
A7: Old Valid PCB:
A8: توزيع نسخ : 1 ـ تحقیق و توسعه 2 ـ توسعه بازار بازنگری 0 کد فرم :18-18-11-02 | K8: عدد شمارشي
A9: Item | B9: Designator | C9: Part Name | D9: Part No. | E9: Type/ Material | F9: Size | G9: QTY | H9: Brand / Supplier | I9: MANA | J9: Note | K9: 1404/12/12 | L9: Alternative
I10: Stock No. | K10: 16:43:15 | L10: Stock No. | M10: Component Name | N10: Part No. | O10: Type/ Material | P10: Size
A11: 1 | B11: C100, C107, C108, C109, C110, C111, C112, C113, C114, C115, C116, C117, C118, C119, C120, C121, C122, C123, C124, C125, C126, C127, C128, C129, C130, C132, C150, C163, C164, C165, C166, C167, C168, C169, C170, C173, C174, C175, C176, C177, C178, C179, C180, C185, C186, C188, C189, C191, C192, C194, C195, C204, C224, C228, C244, C246, C248, C250, C252, C254, C256, C258, C260, C262, C264, C266, C268, C270, C272, C274, C276, C278, C280, C284, C286, C288, C290, C292, C294, C296, C298, C300, C302, C304, C306, C326 | C11: Capacitor, X7R,47N,50V,10% | E11: SMD | F11: 0603(1608) | G11: 86 | H11: According brand list | I11: 1110101 | K11: Valid
A12: 2 | B12: C101, C133, C212, C225, C227, C229, C242, C245, C247, C249, C251, C253, C255, C257, C259, C261, C263, C265, C267, C269, C271, C273, C275, C277, C279, C281, C282, C283, C285, C287, C289, C291, C293, C295, C297, C299, C301, C303, C305, C307 | C12: Capacitor, X7R,10N,50V,10% | E12: SMD | F12: 0402(1005) | G12: 40 | H12: According brand list | I12: 1110569 | K12: Valid*
A13: 3 | B13: C102, C153, C156, C231 | C13: Capacitor, X7R,1U,16V,10% | E13: SMD | F13: 0603(1608) | G13: 4 | H13: According brand list | I13: 1110135 | K13: Valid
A14: 4 | B14: C103, C104, C106, C160, C161, C171, C232, C308, C309, C310, C311, C312, C313, C314, C316, C318, C319, C322, C323, C325 | C14: Capacitor, X7R,100N,50V,10% | E14: SMD | F14: 0402(1005) | G14: 20 | H14: According brand list | I14: 1110118 | K14: Valid
A15: 5 | B15: C105, C154, C155, C157, C162, C172, C190, C193, C196, C197, C198, C202, C203, C222, C223, C230, C334 | C15: Capacitor, X7R,100N,50V,10% | E15: SMD | F15: 0603(1608) | G15: 17 | H15: According brand list | I15: 1110095 | K15: Valid
A16: 6 | B16: C140, C142, C146, C147, C148, C149, C213, C214 | C16: Capacitor, NP0,68P,50V,5% | E16: SMD | F16: 0603(1608) | G16: 8 | H16: According brand list | I16: 1110109 | K16: Valid
A17: 7 | B17: C141, C211 | C17: Capacitor, X7R,10N,50V,10% | E17: SMD | F17: 0603(1608) | G17: 2 | H17: According brand list | I17: 1110075 | K17: Valid
A18: 8 | B18: C143, C144, C159 | C18: Capacitor, X7R,1N,50V,10% | E18: SMD | F18: 0603(1608) | G18: 3 | H18: According brand list | I18: 1110132 | K18: Valid
A19: 9 | B19: C151, C152, C317, C331, C333 | C19: Capacitor, X7R,4.7U,16V,10% | E19: SMD | F19: 1206(3216) | G19: 5 | H19: According brand list | I19: 1102015 | K19: Valid*
A20: 10 | B20: C158 | C20: Capacitor, Electrolytic,100U,16V,20%,85°C | E20: SMD | F20: D<6.3 , L<7 , B=6.6 | G20: 1 | H20: According brand list | I20: 1110032 | K20: Valid | L20: 1110105 | M20: Capacitor, Electrolytic,100U,16V,20%,105°C,-40°C | N20: - | O20: SMD | P20: D<6.3 , L<7 , B=6.6 | Q20: Valid
A21: 11 | B21: C315 | C21: Capacitor, X7R,1N,50V,10% | E21: SMD | F21: 0402(1005) | G21: 1 | H21: According brand list | I21: 1110131 | K21: Valid
A22: 12 | B22: C320, C321 | C22: Capacitor, NP0,10P,50V,5% | E22: SMD | F22: 0402(1005) | G22: 2 | H22: According brand list | I22: 1110128 | K22: Valid
A23: 13 | B23: C324, C327 | C23: Capacitor, X7R,22N,50V,10% | E23: SMD | F23: 0402(1005) | G23: 2 | H23: According brand list | I23: 1110142 | K23: Valid
A24: 14 | B24: D101, D104, D105, D107, D108, D109, D110, D111, D112, D113, D114, D115, D116, D117, D122, D123, D124, D125, D126, D127, D128, D129, D163, D164, D165, D166, D167, D168, D170, D176, D178, D185, D190, D192, D194, D198, D199, D201, D203, D204, D206, D207, D209, D210 | C24: Diode, 1N4007WS | D24: 1N4007WS | E24: SMD | F24: SOD-323 | G24: 44 | H24: MDD | I24: 1110901 | K24: Valid
A25: 15 | B25: D102, D159, D160, D161, D162, D169, D171, D173, D175, D177, D179, D180, D181, D182, D183, D187, D189, D191, D193, D195, D197, D211 | C25: Diode, Switching Diode, 70V,215mA,Dual | D25: SBAV99WT1G | E25: SMD | F25: SOT-323 | G25: 22 | H25: ONSemi | I25: 1110914 | K25: Valid
A26: 16 | B26: D103, D106, D155 | C26: Diode ESD, CAN Bus ESD protection Diode,24V,5A,230W | D26: PESD2CAN | E26: SMD | F26: SOT-23-3 | G26: 3 | H26: NXP | I26: 1110630 | K26: Valid
A27: 17 | B27: D148, D149, D150, D151, D158 | C27: Diode, Ultra Fast Diode, 1000V,1A | D27: US1M | E27: SMD | F27: DO-214AC(SMA) | G27: 5 | H27: VISHAY | I27: 1110920 | K27: Valid
A28: 18 | B28: D208 | C28: Diode Zener, 3.3V,5%,0.5W | D28: MMSZ5226B | E28: SMD | F28: SOD-123 | G28: 1 | H28: MCC | I28: 1101922 | K28: Valid*
A29: 19 | B29: FB100 | C29: Inductor, Ferrite Bead,1 Line,1.8K?@100MHz,0.2A,1.4? | D29: BLM15BD182SH1 | E29: SMD | F29: 0402(1005) | G29: 1 | I29: 1111832 | K29: Valid_P*
A30: 20 | B30: Q100 | C30: TRANSISTOR, Power BJT PNP,-60V,-1A,1.4W | D30: BCP52-16 | G30: 1 | I30: 1110653 | K30: Valid*
A31: 21 | B31: Q101, Q105, Q106, Q108, Q113, Q114, Q116 | C31: Transistor, PNP,500mA,45V | D31: Typical_BC807-40W | E31: SMD | F31: SOT-323 | G31: 7 | H31: According brand list | I31: 1110655 | K31: Valid*
A32: 22 | B32: Q102 | C32: Transistor, PNP,500mA,45V | D32: Typical_BC807-40 | E32: SMD | F32: SOT-23-3 | G32: 1 | H32: According brand list | I32: 1110604 | K32: Valid
A33: 23 | B33: Q103, Q104, Q107, Q109, Q111, Q112, Q115, Q117 | C33: Transistor, NPN,500mA,45V | D33: Typical_BC817-40W | E33: SMD | F33: SOT-323 | G33: 8 | H33: According brand list | I33: 1110654 | K33: Valid*
A34: 24 | B34: R100, R324, R327, R330, R333, R336, R339, R368, R383, R388, R416, R426, R431, R436, R446 | C34: Resistor, 1.8K,5%,1/4W | E34: SMD | F34: 1206(3216) | G34: 15 | H34: According brand list | I34: 1110364 | K34: Valid
A35: 25 | B35: R101, R102, R134, R249, R325, R326, R328, R329, R331, R332, R334, R335, R337, R338, R340, R341, R342, R344, R345, R347, R348, R350, R351, R353, R354, R356, R357, R359, R360, R362, R363, R365, R369, R371, R374, R376, R379, R381, R384, R386, R389, R391, R397, R400, R403, R408, R409, R413, R414, R418, R419, R428, R429, R433, R434, R438, R439, R443, R448, R449 | C35: Resistor, 22K,5%,1/16W | E35: SMD | F35: 0402(1005) | G35: 60 | H35: According brand list | I35: 1110576 | K35: Valid*
A36: 26 | B36: R103, R104, R105, R106, R107, R108, R111, R112, R113, R114, R115, R116, R117, R118, R119, R120, R121, R122, R123, R124, R125, R126, R127, R128 | C36: Resistor, 100,5%,1/10W | E36: SMD | F36: 0603(1608) | G36: 24 | H36: According brand list | I36: 1101036 | K36: Valid
A37: 27 | B37: R109, R236, R237, R250, R260, R261, R294, R299, R450, R461, R469, R474, R476, R477, R479, R480, R482, R484 | C37: Resistor, 10K,5%,1/16W | E37: SMD | F37: 0402(1005) | G37: 18 | H37: According brand list | I37: 1110703 | K37: Valid
A38: 28 | B38: R129, R130, R131, R132, R133, R136, R137, R138, R139, R140, R141, R146, R147, R148, R149, R263, R264, R266, R267, R270, R272, R308, R309, R310, R312, R313, R314, R315, R316, R372, R377, R405, R410, R440, R456, R481 | C38: Resistor, 0R,5%,1/16W | E38: SMD | F38: 0402(1005) | G38: 36 | H38: According brand list | I38: 1110276 | K38: Valid
A39: 29 | B39: R135, R246, R247, R248, R343, R346, R349, R352, R355, R358, R361, R364, R375, R380, R407, R411 | C39: Resistor, 1.2K,5%,1/4W | E39: SMD | F39: 1206(3216) | G39: 16 | H39: According brand list | I39: 1110284 | K39: Valid
A40: 30 | B40: R142, R143 | C40: Resistor, 60.4,1%,1/4W,-55°C,155 °C | D40: AC1206FR-0760R4L | E40: SMD | F40: 1206(3216) | G40: 2 | H40: Yageo | I40: 1110690 | K40: Valid_P(EMS)
...

Sheet top
A1: Designator | B1: Center-X(mm) | C1: Center-Y(mm) | D1: Rotation | E1: SPCO Stock Number | F1: Description
A2: C100 | B2: 96.2477 | C2: 33.926 | D2: 90 | E2: 1110101 | F2: Capacitor,X7R,47N,50V,10%,0603(1608)
A3: C109 | B3: 110.4977 | C3: 34.026 | D3: 270 | E3: 1110101 | F3: Capacitor,X7R,47N,50V,10%,0603(1608)
A4: C110 | B4: 110.4977 | C4: 31.326 | D4: 270 | E4: 1110101 | F4: Capacitor,X7R,47N,50V,10%,0603(1608)
A5: C112 | B5: 110.4977 | C5: 28.676 | D5: 270 | E5: 1110101 | F5: Capacitor,X7R,47N,50V,10%,0603(1608)
A6: C113 | B6: 116.5477 | C6: 34.026 | D6: 270 | E6: 1110101 | F6: Capacitor,X7R,47N,50V,10%,0603(1608)
A7: C114 | B7: 116.5477 | C7: 31.376 | D7: 270 | E7: 1110101 | F7: Capacitor,X7R,47N,50V,10%,0603(1608)
A8: C115 | B8: 116.5477 | C8: 28.726 | D8: 270 | E8: 1110101 | F8: Capacitor,X7R,47N,50V,10%,0603(1608)
A9: C116 | B9: 116.5477 | C9: 26.026 | D9: 270 | E9: 1110101 | F9: Capacitor,X7R,47N,50V,10%,0603(1608)
A10: C132 | B10: 30.3477 | C10: 114.7858 | D10: 180 | E10: 1110101 | F10: Capacitor,X7R,47N,50V,10%,0603(1608)
A11: C133 | B11: 95.0477 | C11: 91.3659 | D11: 90 | E11: 1110569 | F11: Capacitor,X7R,10N,50V,10%,0402(1005)
A12: C140 | B12: 82.0227 | C12: 58.251 | D12: 360 | E12: 1110109 | F12: Capacitor,NP0,68P,50V,5%,0603(1608)
A13: C141 | B13: 87.3477 | C13: 73.051 | D13: 180 | E13: 1110075 | F13: Capacitor,X7R,10N,50V,10%,0603(1608)
... A290: X100 | B290: 74.2417 | C290: 99.5278 | D290: 360 | E290: 1111096 | F290: Crystal, 20.000MHz,20PPM,20PPM,10P,60O,-40°C,85°C,3225

Sheet Sheet1
A1: SPCO Stock Number | B1: Description | C1: top | D1: bot | E1: total
A2: 1110075 | B2: Capacitor, X7R,10N,50V,10%,0603(1608) | C2: =COUNTIFS(#REF!,Sheet1!A2,#REF!,Sheet1!$C$1) | D2: =COUNTIFS(#REF!,Sheet1!A2,#REF!,Sheet1!$D$1) | E2: =D2+C2 | F2: =_xlfn.XLOOKUP(A2,K:K,H:H,0,0) | G2: =F2-E2 | H2: 67 | I2: According brand list | J2: 1110075 | K2: 1110075 | L2: 1 | M2: 1
A3: 1110101 | B3: Capacitor, X7R,47N,50V,10%,0603(1608) | C3: =COUNTIFS(#REF!,Sheet1!A3,#REF!,Sheet1!$C$1) | D3: =COUNTIFS(#REF!,Sheet1!A3,#REF!,Sheet1!$D$1) | E3: =D3+C3 | F3: =_xlfn.XLOOKUP(A3,K:K,H:H,0,0) | G3: =F3-E3 | H3: 93 | I3: According brand list | J3: 1110101 | K3: 1110101
A4: 1110095 | B4: Capacitor, X7R,100N,50V,10%,0603(1608) | C4: =COUNTIFS(#REF!,Sheet1!A4,#REF!,Sheet1!$C$1) | D4: =COUNTIFS(#REF!,Sheet1!A4,#REF!,Sheet1!$D$1) | E4: =D4+C4 | F4: =_xlfn.XLOOKUP(A4,K:K,H:H,0,0) | G4: =F4-E4 | H4: 38 | I4: According brand list | J4: 1110095 | K4: 1110095
A5: 1110109 | B5: Capacitor, NP0,68P,50V,5%,0603(1608) | C5: =COUNTIFS(#REF!,Sheet1!A5,#REF!,Sheet1!$C$1) | D5: =COUNTIFS(#REF!,Sheet1!A5,#REF!,Sheet1!$D$1) | E5: =D5+C5 | F5: =_xlfn.XLOOKUP(A5,K:K,H:H,0,0) | G5: =F5-E5 | H5: 5 | I5: According brand list | J5: 1110109 | K5: 1110109
A6: 1110132 | B6: Capacitor, X7R,1N,50V,10%,0603(1608) | C6: =COUNTIFS(#REF!,Sheet1!A6,#REF!,Sheet1!$C$1) | D6: =COUNTIFS(#REF!,Sheet1!A6,#REF!,Sheet1!$D$1) | E6: =D6+C6 | F6: =_xlfn.XLOOKUP(A6,K:K,H:H,0,0) | G6: =F6-E6 | H6: 15 | I6: According brand list | J6: 1110132 | K6: 1110132
A7: 1110099 | B7: Capacitor, NP0,22P,50V,5%,0603(1608) | C7: =COUNTIFS(#REF!,Sheet1!A7,#REF!,Sheet1!$C$1) | D7: =COUNTIFS(#REF!,Sheet1!A7,#REF!,Sheet1!$D$1) | E7: =D7+C7 | F7: =_xlfn.XLOOKUP(A7,K:K,H:H,0,0) | G7: =F7-E7 | H7: 1 | I7: According brand list | J7: 1110096 | K7: 1110096
A8: 1110090 | B8: Capacitor, Electrolytic,220U,35V,20%,105°C,-40°C,D=10 , L<10 , B=10.3 | C8: =COUNTIFS(#REF!,Sheet1!A8,#REF!,Sheet1!$C$1) | D8: =COUNTIFS(#REF!,Sheet1!A8,#REF!,Sheet1!$D$1) | E8: =D8+C8 | F8: =_xlfn.XLOOKUP(A8,K:K,H:H,0,0) | G8: =F8-E8 | H8: 2 | I8: According brand list | J8: 1110099 | K8: 1110099
A9: 1110105 | B9: Capacitor, Electrolytic,100U,16V,20%,105°C,-40°C,D<6.3 , L<7 , B=6.6 | C9: =COUNTIFS(#REF!,Sheet1!A9,#REF!,Sheet1!$C$1) | D9: =COUNTIFS(#REF!,Sheet1!A9,#REF!,Sheet1!$D$1) | E9: =D9+C9 | F9: =_xlfn.XLOOKUP(A9,K:K,H:H,0,0) | G9: =F9-E9 | H9: 2 | I9: According brand list | J9: 1110090 | K9: 1110090
A10: 1110808 | B10: Diode Zener, 5.6V,2%,0.35W,SOD-123 | C10: =COUNTIFS(#REF!,Sheet1!A10,#REF!,Sheet1!$C$1) | D10: =COUNTIFS(#REF!,Sheet1!A10,#REF!,Sheet1!$D$1) | E10: =D10+C10 | F10: =_xlfn.XLOOKUP(A10,K:K,H:H,0,0) | G10: =F10-E10 | H10: 2 | I10: According brand list | J10: 1110105 | K10: 1110105
A11: 1110630 | B11: Diode ESD, CAN Bus ESD protection Diode,24V,5A,230W,SOT-23-3 | C11: =COUNTIFS(#REF!,Sheet1!A11,#REF!,Sheet1!$C$1) | D11: =COUNTIFS(#REF!,Sheet1!A11,#REF!,Sheet1!$D$1) | E11: =D11+C11 | F11: =_xlfn.XLOOKUP(A11,K:K,H:H,0,0) | G11: =F11-E11 | H11: 7 | I11: NXP | J11: 1110808 | K11: 1110808 | L11: 3 | M11: 0
A12: 1110901 | B12: Diode, General Purpose Rectifier,600V,1A,SOD-323 | C12: =COUNTIFS(#REF!,Sheet1!A12,#REF!,Sheet1!$C$1) | D12: =COUNTIFS(#REF!,Sheet1!A12,#REF!,Sheet1!$D$1) | E12: =D12+C12 | F12: =_xlfn.XLOOKUP(A12,K:K,H:H,0,0) | G12: =F12-E12 | H12: 2 | I12: NXP | J12: 1110630 | K12: 1110630 | L12: 25 | M12: 19
A13: 1110915 | B13: Diode, High Voltage Switching Diode,250V,200mA,SOT-23-3 | C13: =COUNTIFS(#REF!,Sheet1!A13,#REF!,Sheet1!$C$1) | D13: =COUNTIFS(#REF!,Sheet1!A13,#REF!,Sheet1!$D$1) | E13: =D13+C13 | F13: =_xlfn.XLOOKUP(A13,K:K,H:H,0,0) | G13: =F13-E13 | H13: 25 | I13: MDD | J13: 1110901 | K13: 1110901
A14: 1110916 | B14: Diode ESD, LIN-bus ESD protection diode,24_15V,3A,160W,SOD-323 | C14: =COUNTIFS(#REF!,Sheet1!A14,#REF!,Sheet1!$C$1) | D14: =COUNTIFS(#REF!,Sheet1!A14,#REF!,Sheet1!$D$1) | E14: =D14+C14 | F14: =_xlfn.XLOOKUP(A14,K:K,H:H,0,0) | G14: =F14-E14 | H14: 2 | I14: ONSemi | J14: 1110915 | K14: 1110915
A15: 1110914 | B15: Diode, Switching Diode,70V,215mA,Dual,SOT-323 | C15: =COUNTIFS(#REF!,Sheet1!A15,#REF!,Sheet1!$C$1) | D15: =COUNTIFS(#REF!,Sheet1!A15,#REF!,Sheet1!$D$1) | E15: =D15+C15 | F15: =_xlfn.XLOOKUP(A15,K:K,H:H,0,0) | G15: =F15-E15 | H15: 2 | I15: NXP | J15: 1110916 | K15: 1110916 | L15: 8 | M15: 14
A16: 1110303 | B16: Resistor, 4.7K,5%,1/10W,0603(1608) | C16: =COUNTIFS(#REF!,Sheet1!A16,#REF!,Sheet1!$C$1) | D16: =COUNTIFS(#REF!,Sheet1!A16,#REF!,Sheet1!$D$1) | E16: =D16+C16 | F16: =_xlfn.XLOOKUP(A16,K:K,H:H,0,0) | G16: =F16-E16 | H16: 3 | I16: PROTEK | J16: 1110921 | K16: 1110921 | L16: 0 | M16: 6
A17: 1110398 | B17: Resistor, 1.2K,1%,1/10W,0603(1608) | C17: =COUNTIFS(#REF!,Sheet1!A17,#REF!,Sheet1!$C$1) | D17: =COUNTIFS(#REF!,Sheet1!A17,#REF!,Sheet1!$D$1) | E17: =D17+C17 | F17: =_xlfn.XLOOKUP(A17,K:K,H:H,0,0) | G17: =F17-E17 | H17: 4 | I17: VISHAY | J17: 1110920 | K17: 1110920
A18: 1110779 | B18: Resistor, 27K,1%,1/10W,0603(1608) | C18: =COUNTIFS(#REF!,Sheet1!A18,#REF!,Sheet1!$C$1) | D18: =COUNTIFS(#REF!,Sheet1!A18,#REF!,Sheet1!$D$1) | E18: =D18+C18 | F18: =_xlfn.XLOOKUP(A18,K:K,H:H,0,0) | G18: =F18-E18 | H18: 4 | I18: ONSemi | J18: 1110914 | K18: 1110914
A19: 1110702 | B19: Resistor, 10K,1%,1/10W,0603(1608) | C19: =COUNTIFS(#REF!,Sheet1!A19,#REF!,Sheet1!$C$1) | D19: =COUNTIFS(#REF!,Sheet1!A19,#REF!,Sheet1!$D$1) | E19: =D19+C19 | F19: =_xlfn.XLOOKUP(A19,K:K,H:H,0,0) | G19: =F19-E19 | H19: 4 | I19: According brand list | J19: 1110604 | K19: 1110604
A20: 1110183 | B20: Resistor, 10K,5%,1/10W,0603(1608) | C20: =COUNTIFS(#REF!,Sheet1!A20,#REF!,Sheet1!$C$1) | D20: =COUNTIFS(#REF!,Sheet1!A20,#REF!,Sheet1!$D$1) | E20: =D20+C20 | F20: =_xlfn.XLOOKUP(A20,K:K,H:H,0,0) | G20: =F20-E20 | H20: 5 | I20: According brand list | J20: 1110600 | K20: 1110600
A21: 1110274 | B21: Resistor, 0,5%,1/10W,0603(1608) | C21: =COUNTIFS(#REF!,Sheet1!A21,#REF!,Sheet1!$C$1) | D21: =COUNTIFS(#REF!,Sheet1!A21,#REF!,Sheet1!$D$1) | E21: =D21+C21 | F21: =_xlfn.XLOOKUP(A21,K:K,H:H,0,0) | G21: =F21-E21 | H21: 62 | I21: According brand list | J21: 1110303 | K21: 1110303 | L21: 3 | M21: 0
A22: 1110755 | B22: Resistor, 60.4,1%,1/2W,1210(3225) | C22: =COUNTIFS(#REF!,Sheet1!A22,#REF!,Sheet1!$C$1) | D22: =COUNTIFS(#REF!,Sheet1!A22,#REF!,Sheet1!$D$1) | E22: =D22+C22 | F22: =_xlfn.XLOOKUP(A22,K:K,H:H,0,0) | G22: =F22-E22 | H22: 1 | I22: According brand list | J22: 1110398 | K22: 1110398
A23: 1110271 | B23: Resistor, 680,1%,1/2W,1210(3225) | C23: =COUNTIFS(#REF!,Sheet1!A23,#REF!,Sheet1!$C$1) | D23: =COUNTIFS(#REF!,Sheet1!A23,#REF!,Sheet1!$D$1) | E23: =D23+C23 | F23: =_xlfn.XLOOKUP(A23,K:K,H:H,0,0) | G23: =F23-E23 | H23: 1 | I23: According brand list | J23: 1110779 | K23: 1110779
A24: 1110279 | B24: Resistor, 1.4K,1%,1/4W,1206(3216) | C24: =COUNTIFS(#REF!,Sheet1!A24,#REF!,Sheet1!$C$1) | D24: =COUNTIFS(#REF!,Sheet1!A24,#REF!,Sheet1!$D$1) | E24: =D24+C24 | F24: =_xlfn.XLOOKUP(A24,K:K,H:H,0,0) | G24: =F24-E24 | H24: 10 | I24: According brand list | J24: 1110702 | K24: 1110702
A25: 1110337 | B25: Resistor, 22K,5%,1/10W,0603(1608) | C25: =COUNTIFS(#REF!,Sheet1!A25,#REF!,Sheet1!$C$1) | D25: =COUNTIFS(#REF!,Sheet1!A25,#REF!,Sheet1!$D$1) | E25: =D25+C25 | F25: =_xlfn.XLOOKUP(A25,K:K,H:H,0,0) | G25: =F25-E25 | H25: 22 | I25: According brand list | J25: 1110183 | K25: 1110183
A26: 1110766 | B26: Resistor, 43K,1%,1/10W,0603(1608) | C26: =COUNTIFS(#REF!,Sheet1!A26,#REF!,Sheet1!$C$1) | D26: =COUNTIFS(#REF!,Sheet1!A26,#REF!,Sheet1!$D$1) | E26: =D26+C26 | F26: =_xlfn.XLOOKUP(A26,K:K,H:H,0,0) | G26: =F26-E26 | H26: 11 | I26: According brand list | J26: 1110274 | K26: 1110274
A27: 1110708 | B27: Resistor, 1K,5%,1/10W,0603(1608) | C27: =COUNTIFS(#REF!,Sheet1!A27,#REF!,Sheet1!$C$1) | D27: =COUNTIFS(#REF!,Sheet1!A27,#REF!,Sheet1!$D$1) | E27: =D27+C27 | F27: =_xlfn.XLOOKUP(A27,K:K,H:H,0,0) | G27: =F27-E27 | H27: 2 | I27: According brand list | J27: 1110755 | K27: 1110755 | L27: 0 | M27: 2
A28: 1110758 | B28: Resistor, 1K,5%,1/2W,1210(3225) | C28: =COUNTIFS(#REF!,Sheet1!A28,#REF!,Sheet1!$C$1) | D28: =COUNTIFS(#REF!,Sheet1!A28,#REF!,Sheet1!$D$1) | E28: =D28+C28 | F28: =_xlfn.XLOOKUP(A28,K:K,H:H,0,0) | G28: =F28-E28 | H28: 2 | I28: According brand list | J28: 1110271 | K28: 1110271
A29: 1110388 | B29: Resistor, 100K,1%,1/10W,0603(1608) | C29: =COUNTIFS(#REF!,Sheet1!A29,#REF!,Sheet1!$C$1) | D29: =COUNTIFS(#REF!,Sheet1!A29,#REF!,Sheet1!$D$1) | E29: =D29+C29 | F29: =_xlfn.XLOOKUP(A29,K:K,H:H,0,0) | G29: =F29-E29 | H29: 56 | I29: According brand list | J29: 1110279 | K29: 1110279
A30: 1110760 | B30: Resistor, 47,5%,1/10W,0603(1608) | C30: =COUNTIFS(#REF!,Sheet1!A30,#REF!,Sheet1!$C$1) | D30: =COUNTIFS(#REF!,Sheet1!A30,#REF!,Sheet1!$D$1) | E30: =D30+C30 | F30: =_xlfn.XLOOKUP(A30,K:K,H:H,0,0) | G30: =F30-E30 | H30: 56 | I30: According brand list | J30: 1110337 | K30: 1110337 | L30: 3 | M30: 0
A31: 1110749 | B31: Resistor, 47K,1%,1/10W,0603(1608) | C31: =COUNTIFS(#REF!,Sheet1!A31,#REF!,Sheet1!$C$1) | D31: =COUNTIFS(#REF!,Sheet1!A31,#REF!,Sheet1!$D$1) | E31: =D31+C31 | F31: =_xlfn.XLOOKUP(A31,K:K,H:H,0,0) | G31: =F31-E31 | H31: 52 | I31: According brand list | J31: 1110766 | K31: 1110766
A32: 1110277 | B32: Resistor, 0,5%,1/4W,1206(3216) | C32: =COUNTIFS(#REF!,Sheet1!A32,#REF!,Sheet1!$C$1) | D32: =COUNTIFS(#REF!,Sheet1!A32,#REF!,Sheet1!$D$1) | E32: =D32+C32 | F32: =_xlfn.XLOOKUP(A32,K:K,H:H,0,0) | G32: =F32-E32 | H32: 5 | I32: According brand list | J32: 1110708 | K32: 1110708 | L32: 1 | M32: 0
A33: 1110763 | B33: Resistor, 300K,1%,1/10W,0603(1608) | C33: =COUNTIFS(#REF!,Sheet1!A33,#REF!,Sheet1!$C$1) | D33: =COUNTIFS(#REF!,Sheet1!A33,#REF!,Sheet1!$D$1) | E33: =D33+C33 | F33: =_xlfn.XLOOKUP(A33,K:K,H:H,0,0) | G33: =F33-E33 | H33: 2 | I33: According brand list | J33: 1110758 | K33: 1110758
A34: 1110764 | B34: Resistor, 10m,1%,3W,1225(3263) | C34: =COUNTIFS(#REF!,Sheet1!A34,#REF!,Sheet1!$C$1) | D34: =COUNTIFS(#REF!,Sheet1!A34,#REF!,Sheet1!$D$1) | E34: =D34+C34 | F34: =_xlfn.XLOOKUP(A34,K:K,H:H,0,0) | G34: =F34-E34 | H34: 2 | I34: According brand list | J34: 1110388 | K34: 1110388
A35: 1110502 | B35: IC, MCU,32-Bit Microcontroller,RH850/F1L,LFQFP-176 | C35: =COUNTIFS(#REF!,Sheet1!A35,#REF!,Sheet1!$C$1) | D35: =COUNTIFS(#REF!,Sheet1!A35,#REF!,Sheet1!$D$1) | E35: =D35+C35 | F35: =_xlfn.XLOOKUP(A35,K:K,H:H,0,0) | G35: =F35-E35 | H35: 22 | I35: According brand list | J35: 1110749 | K35: 1110749
A36: 1110460 | B36: IC, CAN tranceiver,SO-8 | C36: =COUNTIFS(#REF!,Sheet1!A36,#REF!,Sheet1!$C$1) | D36: =COUNTIFS(#REF!,Sheet1!A36,#REF!,Sheet1!$D$1) | E36: =D36+C36 | F36: =_xlfn.XLOOKUP(A36,K:K,H:H,0,0) | G36: =F36-E36 | H36: 12 | I36: According brand list | J36: 1110760 | K36: 1110760
A37: 1110456 | B37: IC, CAN tranceiver,SO-14 | C37: =COUNTIFS(#REF!,Sheet1!A37,#REF!,Sheet1!$C$1) | D37: =COUNTIFS(#REF!,Sheet1!A37,#REF!,Sheet1!$D$1) | E37: =D37+C37 | F37: =_xlfn.XLOOKUP(A37,K:K,H:H,0,0) | G37: =F37-E37 | H37: 2 | I37: According brand list | J37: 1110277 | K37: 1110277
A38: 1110401 | B38: IC, ULQ,Seven Darlington array,SO-16 | C38: =COUNTIFS(#REF!,Sheet1!A38,#REF!,Sheet1!$C$1) | D38: =COUNTIFS(#REF!,Sheet1!A38,#REF!,Sheet1!$D$1) | E38: =D38+C38 | F38: =_xlfn.XLOOKUP(A38,K:K,H:H,0,0) | G38: =F38-E38 | H38: 5 | I38: According brand list | J38: 1110747 | K38: 1110747
A39: 1111016 | B39: IC, LIN Transceiver,PG-DSO-8-16 | C39: =COUNTIFS(#REF!,Sheet1!A39,#REF!,Sheet1!$C$1) | D39: =COUNTIFS(#REF!,Sheet1!A39,#REF!,Sheet1!$D$1) | E39: =D39+C39 | F39: =_xlfn.XLOOKUP(A39,K:K,H:H,0,0) | G39: =F39-E39 | H39: 1 | I39: According brand list | J39: 1110761 | K39: 1110761
A40: 1110506 | B40: IC, BTS7030-2EPA,TSDSO-14 | C40: =COUNTIFS(#REF!,Sheet1!A40,#REF!,Sheet1!$C$1) | D40: =COUNTIFS(#REF!,Sheet1!A40,#REF!,Sheet1!$D$1) | E40: =D40+C40 | F40: =_xlfn.XLOOKUP(A40,K:K,H:H,0,0) | G40: =F40-E40 | H40: 2 | I40: According brand list | J40: 1110762 | K40: 1110762 | L40: 3 | M40: 0
...

Sheet bot
A1: Designator | B1: Center-X(mm) | C1: Center-Y(mm) | D1: Rotation | E1: SPCO Stock Number | F1: Description
A2: C101 | B2: 56.4231 | C2: 99.051 | D2: 180 | E2: 1110569 | F2: Capacitor,X7R,10N,50V,10%,0402(1005)
A3: C102 | B3: 104.8227 | C3: 36.651 | D3: 360 | E3: 1110135 | F3: Capacitor,X7R,1U,16V,10%,0603(1608)
A4: C103 | B4: 106.7977 | C4: 35.701 | D4: 90 | E4: 1110118 | F4: Capacitor,X7R,100N,50V,10%,0402(1005)
A5: C104 | B5: 101.7477 | C5: 36.101 | D5: 180 | E5: 1110118 | F5: Capacitor,X7R,100N,50V,10%,0402(1005)
A6: C105 | B6: 104.7727 | C6: 26.001 | D6: 360 | E6: 1110095 | F6: Capacitor,X7R,100N,50V,10%,0603(1608)
A7: C106 | B7: 97.0477 | C7: 36.101 | D7: 360 | E7: 1110118 | F7: Capacitor,X7R,100N,50V,10%,0402(1005)
A8: C107 | B8: 98.9227 | C8: 63.001 | D8: 360 | E8: 1110101 | F8: Capacitor,X7R,47N,50V,10%,0603(1608)
A9: C108 | B9: 93.6227 | C9: 63.001 | D9: 360 | E9: 1110101 | F9: Capacitor,X7R,47N,50V,10%,0603(1608)
A10: C111 | B10: 31.4227 | C10: 60.051 | D10: 360 | E10: 1110101 | F10: Capacitor,X7R,47N,50V,10%,0603(1608)
A11: C117 | B11: 110.4977 | C11: 31.326 | D11: 270 | E11: 1110101 | F11: Capacitor,X7R,47N,50V,10%,0603(1608)
A12: C118 | B12: 110.4977 | C12: 28.676 | D12: 270 | E12: 1110101 | F12: Capacitor,X7R,47N,50V,10%,0603(1608)
A13: C119 | B13: 116.5477 | C13: 31.376 | D13: 270 | E13: 1110101 | F13: Capacitor,X7R,47N,50V,10%,0603(1608)
... A290: U110 | B290: 73.8477 | C290: 60.501 | D290: 270 | E290: 1111097 | F290: IC,Interface,CAN Tranceiver,1/1,SO-14
